Workbook

Sheet Instrucciones
B2: Backlog de desarrollo — Aprendizaje USCO
B3: Sprints, épicas, tareas y subtareas para importar/replicar en Jira (versión 3, 30/09/2026)
B5: Equipo: | C5: Juan David Polanco Ortiz · Nicolás Pérez Varón · Jorel Sebastian Vargas Ibarra · Fernando Andrés Pérez Polanco
B6: Fecha de entrega del MVP: | C6: jueves 12 de noviembre de 2026 (congelamiento del MVP; sustentación el 15 de noviembre)
B7: Duración de sprint: | C7: 11 a 12 días (4 sprints, del 28 de septiembre al 12 de noviembre de 2026). Replanificado el 28/09/2026: el Sprint 1 original (16 sep – 1 oct) no alcanzó a iniciar.
B8: Capacidad estimada del equipo: | C8: 4 integrantes x ~15 h/semana c/u ≈ 94-103 h por sprint (ver hoja "Carga por integrante")
B10: Cómo usar este archivo
B11: 1. La hoja "Backlog" trae una fila por historia/tarea y, debajo, sus subtareas (fondo gris, columna "ID padre"). Cada fila tiene descripción, criterios de aceptación, responsable, etiquetas y fechas.
B12: 2. Importación CSV en Jira: exporten la hoja Backlog a CSV (UTF-8) y en el asistente mapeen ID → Issue Id, ID padre → Parent Id, Tipo → Issue Type (use los nombres de su Jira: Historia/Tarea/Subtarea), Resumen → Summary, "Descripción completa (para Jira)" → Description, Estimación (h) → Original Estimate (en horas), Fecha fin → Due date, Prioridad → Priority, Responsable → Assignee, Etiquetas → Labels, Sprint → Sprint (los sprints deben existir antes con el mismo nombre). Las épicas se enlazan con la columna Épica (Epic Link / Parent según el tipo de proyecto). Si ya crearon las tarjetas a mano, usen esta hoja para crear las subtareas y copiar descripciones y criterios.
B13: 3. Responsables: cada subtarea tiene su propio responsable (por ejemplo, el login tiene subtareas de backend para Jorel y de frontend para Fernando). La hoja "Carga por integrante" suma subtareas y tareas sin subtareas.
B14: 4. Estimaciones: solo llevan horas las subtareas y las tareas sin subtareas; la columna "Total con subtareas" muestra la suma del padre. Jira también suma las subtareas en el padre (Σ).
B15: 5. La columna "Requisito relacionado" enlaza cada tarea con el RF-xx / RNF-xx / CA-xx ya definidos en los capítulos 3 y 4 del informe, para mantener trazabilidad entre lo planeado y lo implementado.
B16: 6. La columna "Descripción" detalla qué debe quedar hecho en cada tarea; úsenla como base de la descripción de la tarjeta en Jira y, si hace falta, descompónganla en subtareas.
B17: 7. Actualicen "Estado" (Por hacer / En curso / En revisión / Hecho). Las filas marcadas "Nueva en v3" en la nota no existían en la versión anterior.

Sheet Resumen de sprints
A1: Sprint | B1: Periodo | C1: Objetivo del sprint | D1: Épicas incluidas | E1: Horas estimadas (backlog) | F1: Entregable principal
A2: Sprint 1 | B2: 28 sep – 8 oct 2026 | C2: Dejar lista la infraestructura del proyecto (repositorio, entornos, base de datos, autenticación) e iniciar el módulo de diagnóstico. | D2: EPIC-1, EPIC-2 (inicio) | E2: =SUMIF(Backlog!$E:$E,A2,Backlog!$J:$J) -> 85 | F2: Entorno de desarrollo funcional, autenticación por rol operativa y modelo de datos del diagnóstico creado.
A3: Sprint 2 | B3: 9 oct – 20 oct 2026 | C3: Completar el módulo de diagnóstico (aplicación, calificación y categorización), iniciar el motor de práctica adaptativa y definir el protocolo de usabilidad. | D3: EPIC-2 (cierre), EPIC-3 (inicio), EPIC-7 (inicio) | E3: =SUMIF(Backlog!$E:$E,A3,Backlog!$J:$J) -> 107 | F3: Prueba diagnóstica funcional de extremo a extremo y banco de ejercicios modelado.
A4: Sprint 3 | B4: 21 oct – 1 nov 2026 | C4: Terminar la práctica adaptativa con retroalimentación inmediata, construir los tableros de seguimiento y analítica, e iniciar la gestión de contenidos. | D4: EPIC-3 (cierre), EPIC-4, EPIC-5 (inicio), EPIC-7 (rendimiento) | E4: =SUMIF(Backlog!$E:$E,A4,Backlog!$J:$J) -> 108 | F4: Módulo de ejercicios interactivos operativo y dashboards de estudiante/docente con datos reales.
A5: Sprint 4 | B5: 2 nov – 12 nov 2026 | C5: Cerrar administración, integrar todos los módulos, ejecutar pruebas de seguridad, concurrencia y validación con usuarios, y empaquetar la entrega del MVP. | D5: EPIC-5 (cierre), EPIC-6, EPIC-7 (cierre) | E5: =SUMIF(Backlog!$E:$E,A5,Backlog!$J:$J) -> 100 | F5: MVP integrado, probado frente a los 16 criterios de aceptación y validado con usuarios piloto — listo para sustentación.
A6: Total | E6: =SUM(E2:E5) -> 400
A8: Horas ya completadas (Estado = Hecho) | E8: =SUMIF(Backlog!$O:$O,"Hecho",Backlog!$J:$J) -> 16
A9: Las horas se suman sobre las filas con estimación propia (subtareas y tareas sin subtareas), así no se cuentan dos veces.

Sheet Carga por integrante
A1: Carga estimada por integrante y sprint (horas)
A2: Se calcula desde la hoja Backlog (columnas Sprint, Estimación y Responsable, incluidas las subtareas). Si reasignan una tarea o subtarea, esta tabla se actualiza sola.
A4: Integrante | B4: Rol principal | C4: Sprint 1 | D4: Sprint 2 | E4: Sprint 3 | F4: Sprint 4 | G4: Total (h) | H4: Promedio h/semana
A5: Jorel Vargas | B5: Backend tecnico: repositorios, arquitectura, autenticación/seguridad, motor adaptativo, historial, administración, entrega. | C5: =SUMIFS(Backlog!$J:$J,Backlog!$P:$P,$A5,Backlog!$E:$E,C$4) -> 30 | D5: =SUMIFS(Backlog!$J:$J,Backlog!$P:$P,$A5,Backlog!$E:$E,D$4) -> 28 | E5: =SUMIFS(Backlog!$J:$J,Backlog!$P:$P,$A5,Backlog!$E:$E,E$4) -> 23 | F5: =SUMIFS(Backlog!$J:$J,Backlog!$P:$P,$A5,Backlog!$E:$E,F$4) -> 28 | G5: =SUM(C5:F5) -> 109 | H5: =G5/$C$14 -> 16.586957
A6: Juan David Polanco | B6: Backend y datos: esquema PostgreSQL y migraciones, servicios de diagnóstico, intentos e indicadores, integración y corrección de incidencias. | C6: =SUMIFS(Backlog!$J:$J,Backlog!$P:$P,$A6,Backlog!$E:$E,C$4) -> 19 | D6: =SUMIFS(Backlog!$J:$J,Backlog!$P:$P,$A6,Backlog!$E:$E,D$4) -> 28 | E6: =SUMIFS(Backlog!$J:$J,Backlog!$P:$P,$A6,Backlog!$E:$E,E$4) -> 30 | F6: =SUMIFS(Backlog!$J:$J,Backlog!$P:$P,$A6,Backlog!$E:$E,F$4) -> 24 | G6: =SUM(C6:F6) -> 101 | H6: =G6/$C$14 -> 15.369565
A7: Nicolás Pérez | B7: Frontend: tema, enrutador y layouts, staging, pantallas de diagnóstico y práctica, MathText, panel admin, accesibilidad y documentación. | C7: =SUMIFS(Backlog!$J:$J,Backlog!$P:$P,$A7,Backlog!$E:$E,C$4) -> 15 | D7: =SUMIFS(Backlog!$J:$J,Backlog!$P:$P,$A7,Backlog!$E:$E,D$4) -> 25 | E7: =SUMIFS(Backlog!$J:$J,Backlog!$P:$P,$A7,Backlog!$E:$E,E$4) -> 25 | F7: =SUMIFS(Backlog!$J:$J,Backlog!$P:$P,$A7,Backlog!$E:$E,F$4) -> 24 | G7: =SUM(C7:F7) -> 89 | H7: =G7/$C$14 -> 13.543478
A8: Fernando Pérez | B8: Frontend y calidad: login y sesión, CI, banco de ítems y ejercicios, categorización, dashboards, pruebas, usabilidad (SUS) y validación piloto. | C8: =SUMIFS(Backlog!$J:$J,Backlog!$P:$P,$A8,Backlog!$E:$E,C$4) -> 21 | D8: =SUMIFS(Backlog!$J:$J,Backlog!$P:$P,$A8,Backlog!$E:$E,D$4) -> 26 | E8: =SUMIFS(Backlog!$J:$J,Backlog!$P:$P,$A8,Backlog!$E:$E,E$4) -> 30 | F8: =SUMIFS(Backlog!$J:$J,Backlog!$P:$P,$A8,Backlog!$E:$E,F$4) -> 24 | G8: =SUM(C8:F8) -> 101 | H8: =G8/$C$14 -> 15.369565
A9: Total equipo | C9: =SUM(C5:C8) -> 85 | D9: =SUM(D5:D8) -> 107 | E9: =SUM(E5:E8) -> 108 | F9: =SUM(F5:F8) -> 100 | G9: =SUM(G5:G8) -> 400
A10: Capacidad del equipo | B10: Días del sprint / 7 × h por semana × 4 integrantes | C10: =ROUND(C13/7*$C$15*4,0) -> 94 | D10: =ROUND(D13/7*$C$15*4,0) -> 103 | E10: =ROUND(E13/7*$C$15*4,0) -> 103 | F10: =ROUND(F13/7*$C$15*4,0) -> 94 | G10: =SUM(C10:F10) -> 394
A11: Holgura (capacidad − carga) | B11: Negativo = sprint sobrecargado | C11: =C10-C9 -> 9 | D11: =D10-D9 -> -4 | E11: =E10-E9 -> -5 | F11: =F10-F9 -> -6 | G11: =G10-G9 -> -6
A13: Días por sprint | B13: Días calendario de cada sprint (fechas de la hoja Resumen de sprints) | C13: 11 | D13: 12 | E13: 12 | F13: 11
A14: Semanas totales | B14: 28 sep – 12 nov 2026 | C14: =SUM(C13:F13)/7 -> 6.5714286
A15: h/semana por persona | B15: Supuesto editable (el backlog original planteaba 12-15 h/semana) | C15: 15
A17: Celdas en azul con fondo amarillo: supuestos que pueden ajustar.

Sheet Épicas
A1: ID | B1: Nombre de la épica | C1: Descripción | D1: Requisitos relacionados (cap. 3-4) | E1: Sprints
A2: EPIC-1 | B2: Configuración base, infraestructura y autenticación | C2: Repositorio, entornos de frontend/backend, esquema inicial de base de datos, autenticación y control de acceso por rol. | D2: RF-01, RNF-03 | E2: Sprint 1
A3: EPIC-2 | B3: Módulo de diagnóstico | C3: Aplicación de la prueba diagnóstica, cálculo automático del puntaje y asignación de categoría de desempeño. | D3: RF-02, RF-03, RF-04 | E3: Sprint 1 - Sprint 2
A4: EPIC-3 | B4: Práctica adaptativa y retroalimentación | C4: Banco de ejercicios por competencia, motor de asignación según desempeño, retroalimentación inmediata y registro de intentos. | D4: RF-05, RF-06, RF-07, RF-08, RF-14, RF-16 | E4: Sprint 2 - Sprint 3
A5: EPIC-4 | B5: Seguimiento del progreso y analítica de aprendizaje | C5: Indicadores de progreso, dashboard para estudiantes y docentes, historial de resultados e indicadores derivados de analítica. Incluye grupos y asociación docente–estudiante (nuevo en v3). | D5: RF-09, RF-10, RF-11, RF-15 | E5: Sprint 3
A6: EPIC-5 | B6: Gestión de contenidos y administración | C6: Gestión de actividades/contenidos por el docente y administración de usuarios y roles por el administrador. | D6: RF-12, RF-13 | E6: Sprint 3 - Sprint 4
A7: EPIC-6 | B7: Integración, pruebas y validación del MVP | C7: Integración end-to-end, pruebas funcionales frente a los criterios de aceptación, validación con usuarios piloto, documentación y cierre de la entrega. | D7: CA-01 a CA-16 | E7: Sprint 4
A8: EPIC-7 | B8: Calidad: usabilidad, rendimiento y seguridad | C8: Protocolo y medición de usabilidad, pruebas de rendimiento de servicios críticos, hardening de seguridad por rol y prueba de concurrencia. | D8: RNF-01, RNF-02, RNF-03, RNF-04 | E8: Sprint 2 - Sprint 4

Sheet Backlog
A1: ID | B1: ID padre | C1: Tipo | D1: Épica | E1: Sprint | F1: Resumen (Summary) | G1: Descripción | H1: Criterios de aceptación | I1: Requisito relacionado | J1: Estimación (h) | K1: Total con subtareas (h) | L1: Fecha inicio | M1: Fecha fin | N1: Prioridad | O1: Estado | P1: Responsable (Assignee) | Q1: Etiquetas (Labels) | R1: Nota de coordinación | S1: Descripción completa (para Jira)
A2: 1 | C2: Tarea | D2: EPIC-1 | E2: Sprint 1 | F2: Crear repositorio y flujo de trabajo Git | G2: Organización de GitHub, repositorios aprendizaje-usco-backend y aprendizaje-usco-frontend, ramas main y develop, develop como rama por defecto, rulesets (PR obligatorio, 1 aprobación, sin force push) e invitación del equipo. | H2: • Ambos repositorios existen en la organización con main y develop. • No se puede hacer push directo a main ni a develop. • Los cuatro integrantes tienen permiso de escritura. | I2: - | J2: 4 | K2: =IF(COUNTIF($B$2:$B$150,A2)>0,SUMIFS($J$2:$J$150,$B$2:$B$150,A2)+N(J2),J2) -> 4 | L2: 28/09/2026 | M2: 08/10/2026 | N2: Alta | O2: Hecho | P2: Jorel Vargas | Q2: devops | S2: =G2&IF(H2="","",CHAR(10)&CHAR(10)&"Criterios de aceptación:"&CHAR(10)&H2) -> Organización de GitHub, repositorios aprendizaje-usco-backend y aprendizaje-usco-frontend, ramas main y develop, develop como rama por defecto, rulesets (PR obligatorio, 1 aprobación, sin force push) e invitación del equipo. Criterios de aceptación: • Ambos repositorios existen en la organización con main y develop. • No se puede hacer push directo a main ni a develop. • Los cuatro integrantes tienen permiso de escritura.
A3: 2 | C3: Tarea | D3: EPIC-1 | E3: Sprint 1 | F3: Documentación base de los repositorios | G3: README.md de backend y frontend (instalación, comandos, variables de entorno, estructura, responsables, problemas frecuentes), CONTRIBUTING.md común y plantilla de pull request en .github/. | H3: • Un integrante nuevo puede levantar ambos proyectos siguiendo solo los README. • La plantilla de PR aparece al abrir un pull request. | I3: - | J3: 2 | K3: =IF(COUNTIF($B$2:$B$150,A3)>0,SUMIFS($J$2:$J$150,$B$2:$B$150,A3)+N(J3),J3) -> 2 | L3: 28/09/2026 | M3: 08/10/2026 | N3: Media | O3: Hecho | P3: Jorel Vargas | Q3: docs | R3: Nueva en v3 | S3: =G3&IF(H3="","",CHAR(10)&CHAR(10)&"Criterios de aceptación:"&CHAR(10)&H3) -> README.md de backend y frontend (instalación, comandos, variables de entorno, estructura, responsables, problemas frecuentes), CONTRIBUTING.md común y plantilla de pull request en .github/. Criterios de aceptación: • Un integrante nuevo puede levantar ambos proyectos siguiendo solo los README. • La plantilla de PR aparece al abrir un pull request.
A4: 3 | C4: Tarea | D4: EPIC-1 | E4: Sprint 1 | F4: Configurar proyecto backend (Spring Boot) | G4: Proyecto Spring Boot 4.1 / Java 21 generado con Initializr, organizado por módulo funcional con capas internas (controller, service, repository, dto, entity), perfiles dev/test y conexión a PostgreSQL con Docker Compose. | H4: • ./mvnw spring-boot:run levanta la API y /actuator/health responde UP. • Swagger UI carga en /swagger-ui.html. • Cualquier error de la API responde con el formato JSON estándar. | I4: - | K4: =IF(COUNTIF($B$2:$B$150,A4)>0,SUMIFS($J$2:$J$150,$B$2:$B$150,A4)+N(J4),J4) -> 10 | L4: 28/09/2026 | M4: 08/10/2026 | N4: Alta | O4: En curso | P4: Jorel Vargas | Q4: backend | S4: =G4&IF(H4="","",CHAR(10)&CHAR(10)&"Criterios de aceptación:"&CHAR(10)&H4) -> Proyecto Spring Boot 4.1 / Java 21 generado con Initializr, organizado por módulo funcional con capas internas (controller, service, repository, dto, entity), perfiles dev/test y conexión a PostgreSQL con Docker Compose. Criterios de aceptación: • ./mvnw spring-boot:run levanta la API y /actuator/health responde UP. • Swagger UI carga en /swagger-ui.html. • Cualquier error de la API responde con el formato JSON estándar.
A5: 4 | B5: 3 | C5: Subtarea | D5: EPIC-1 | E5: Sprint 1 | F5: Generar el proyecto con Initializr y sus dependencias | G5: Spring Web, Data JPA, PostgreSQL, Flyway, Security, OAuth2 Resource Server, Validation, Lombok, DevTools, Actuator, Docker Compose, Testcontainers + springdoc 3.x. | H5: • Compila y la prueba generada pasa. | J5: 3 | L5: 28/09/2026 | M5: 08/10/2026 | N5: Alta | O5: Hecho | P5: Jorel Vargas | Q5: backend | S5: =G5&IF(H5="","",CHAR(10)&CHAR(10)&"Criterios de aceptación:"&CHAR(10)&H5) -> Spring Web, Data JPA, PostgreSQL, Flyway, Security, OAuth2 Resource Server, Validation, Lombok, DevTools, Actuator, Docker Compose, Testcontainers + springdoc 3.x. Criterios de aceptación: • Compila y la prueba generada pasa.
A6: 5 | B6: 3 | C6: Subtarea | D6: EPIC-1 | E6: Sprint 1 | F6: Configurar perfiles, compose.yaml y application.yml | G6: application.yml común, application-dev.yml, application-test.yml, PostgreSQL 17 en compose.yaml, ddl-auto: validate. | H6: • La app conecta a PostgreSQL local en perfil dev. | J6: 2 | L6: 28/09/2026 | M6: 08/10/2026 | N6: Alta | O6: Hecho | P6: Jorel Vargas | Q6: backend | S6: =G6&IF(H6="","",CHAR(10)&CHAR(10)&"Criterios de aceptación:"&CHAR(10)&H6) -> application.yml común, application-dev.yml, application-test.yml, PostgreSQL 17 en compose.yaml, ddl-auto: validate. Criterios de aceptación: • La app conecta a PostgreSQL local en perfil dev.
A7: 6 | B7: 3 | C7: Subtarea | D7: EPIC-1 | E7: Sprint 1 | F7: Crear estructura de paquetes y SecurityConfig mínima | G7: Paquetes config, security, common, usuario, diagnostico, practica, contenido, progreso, analitica. SecurityConfig con rutas públicas (/api/auth/**, health, Swagger). | H7: • Health y Swagger accesibles sin token; el resto devuelve 401. | J7: 2 | L7: 28/09/2026 | M7: 08/10/2026 | N7: Alta | O7: Hecho | P7: Jorel Vargas | Q7: backend | S7: =G7&IF(H7="","",CHAR(10)&CHAR(10)&"Criterios de aceptación:"&CHAR(10)&H7) -> Paquetes config, security, common, usuario, diagnostico, practica, contenido, progreso, analitica. SecurityConfig con rutas públicas (/api/auth/**, health, Swagger). Criterios de aceptación: • Health y Swagger accesibles sin token; el resto devuelve 401.
A8: 7 | B8: 3 | C8: Subtarea | D8: EPIC-1 | E8: Sprint 1 | F8: Manejador global de errores y formato estándar | G8: En common/: clase ErrorResponse (timestamp, status, message, path), @RestControllerAdvice que traduce MethodArgumentNotValidException (400, con los campos inválidos), EntityNotFound/ResourceNotFound propia (404), DataIntegrityViolation (409) y Exception genérica (500 sin exponer la traza). Excepciones propias: RecursoNoEncontradoException, ConflictoException, ReglaNegocioException. | H8: • Un DTO inválido devuelve 400 con la lista de campos y mensajes. • Un id inexistente devuelve 404 con el formato estándar. • Un error inesperado devuelve 500 sin stack trace en la respuesta. | J8: 2 | L8: 02/10/2026 | M8: 04/10/2026 | N8: Alta | O8: Por hacer | P8: Juan David Polanco | Q8: backend | S8: =G8&IF(H8="","",CHAR(10)&CHAR(10)&"Criterios de aceptación:"&CHAR(10)&H8) -> En common/: clase ErrorResponse (timestamp, status, message, path), @RestControllerAdvice que traduce MethodArgumentNotValidException (400, con los campos inválidos), EntityNotFound/ResourceNotFound propia (404), DataIntegrityViolation (409) y Exception genérica (500 sin exponer la traza). Excepciones propias: RecursoNoEncontradoException, ConflictoException, ReglaNegocioException. Criterios de aceptación: • Un DTO inválido devuelve 400 con la lista de campos y mensajes. • Un id inexistente devuelve 404 con el formato estándar. • Un error inesperado devuelve 500 sin stack trace en la respuesta.
A9: 8 | B9: 3 | C9: Subtarea | D9: EPIC-1 | E9: Sprint 1 | F9: Configurar CORS y seguridad Bearer en Swagger | G9: CorsConfigurationSource leyendo app.cors.allowed-origins (métodos GET, POST, PUT, PATCH, DELETE; header Authorization). En OpenAPI, esquema de seguridad bearerAuth (JWT) para poder probar endpoints protegidos con el botón Authorize. | H9: • El frontend en localhost:5173 consume la API sin errores de CORS. • Desde Swagger se puede pegar un token y llamar un endpoint protegido. | J9: 1 | L9: 30/09/2026 | M9: 01/10/2026 | N9: Alta | O9: Por hacer | P9: Jorel Vargas | Q9: backend | S9: =G9&IF(H9="","",CHAR(10)&CHAR(10)&"Criterios de aceptación:"&CHAR(10)&H9) -> CorsConfigurationSource leyendo app.cors.allowed-origins (métodos GET, POST, PUT, PATCH, DELETE; header Authorization). En OpenAPI, esquema de seguridad bearerAuth (JWT) para poder probar endpoints protegidos con el botón Authorize. Criterios de aceptación: • El frontend en localhost:5173 consume la API sin errores de CORS. • Desde Swagger se puede pegar un token y llamar un endpoint protegido.
A10: 9 | C10: Tarea | D10: EPIC-1 | E10: Sprint 1 | F10: Configurar proyecto frontend (React) | G10: Proyecto Vite 8 + React en JavaScript con react-router, axios, MUI, recharts, KaTeX, react-hook-form y zod; estructura por features; enrutador con todas las rutas del README; layouts por rol y tema institucional. | H10: • npm run dev, lint y build sin errores. • Todas las rutas del README existen (aunque sea con página provisional) y cada rol ve su propio menú. • La interfaz usa los colores USCO desde el tema, no colores sueltos. | I10: - | K10: =IF(COUNTIF($B$2:$B$150,A10)>0,SUMIFS($J$2:$J$150,$B$2:$B$150,A10)+N(J10),J10) -> 10 | L10: 28/09/2026 | M10: 08/10/2026 | N10: Alta | O10: En curso | P10: Nicolás Pérez | Q10: frontend | R10: Jorel creó el esqueleto; Nicolás completa enrutador, layouts y tema. | S10: =G10&IF(H10="","",CHAR(10)&CHAR(10)&"Criterios de aceptación:"&CHAR(10)&H10) -> Proyecto Vite 8 + React en JavaScript con react-router, axios, MUI, recharts, KaTeX, react-hook-form y zod; estructura por features; enrutador con todas las rutas del README; layouts por rol y tema institucional. Criterios de aceptación: • npm run dev, lint y build sin errores. • Todas las rutas del README existen (aunque sea con página provisional) y cada rol ve su propio menú. • La interfaz usa los colores USCO desde el tema, no colores sueltos.
A11: 10 | B11: 9 | C11: Subtarea | D11: EPIC-1 | E11: Sprint 1 | F11: Crear proyecto con Vite, librerías, estructura, .env y cliente axios | G11: Plantilla react, dependencias de la guía, carpetas api/ routes/ context/ layouts/ features/ components/ theme/ utils/, VITE_API_URL, api/client.js con interceptor de token, Prettier. | H11: • El proyecto corre en localhost:5173. | J11: 3 | L11: 28/09/2026 | M11: 08/10/2026 | N11: Alta | O11: Hecho | P11: Jorel Vargas | Q11: frontend | S11: =G11&IF(H11="","",CHAR(10)&CHAR(10)&"Criterios de aceptación:"&CHAR(10)&H11) -> Plantilla react, dependencias de la guía, carpetas api/ routes/ context/ layouts/ features/ components/ theme/ utils/, VITE_API_URL, api/client.js con interceptor de token, Prettier. Criterios de aceptación: • El proyecto corre en localhost:5173.
A12: 11 | B12: 9 | C12: Subtarea | D12: EPIC-1 | E12: Sprint 1 | F12: Tema de MUI con los colores USCO | G12: theme/theme.js: palette.primary con el rojo/vino institucional y palette.secondary tomados del prototipo HTML; tipografía, border radius y breakpoints; CssBaseline. Verificar contraste de texto sobre primary (mínimo 4.5:1, WCAG AA) con un verificador de contraste. | H12: • ThemeProvider envuelve la app en main.jsx. • Botones, AppBar y enlaces toman el color del tema. • El contraste texto/fondo de los colores principales cumple 4.5:1. | J12: 2 | L12: 30/09/2026 | M12: 01/10/2026 | N12: Alta | O12: Por hacer | P12: Nicolás Pérez | Q12: frontend | S12: =G12&IF(H12="","",CHAR(10)&CHAR(10)&"Criterios de aceptación:"&CHAR(10)&H12) -> theme/theme.js: palette.primary con el rojo/vino institucional y palette.secondary tomados del prototipo HTML; tipografía, border radius y breakpoints; CssBaseline. Verificar contraste de texto sobre primary (mínimo 4.5:1, WCAG AA) con un verificador de contraste. Criterios de aceptación: • ThemeProvider envuelve la app en main.jsx. • Botones, AppBar y enlaces toman el color del tema. • El contraste texto/fondo de los colores principales cumple 4.5:1.
A13: 12 | B13: 9 | C13: Subtarea | D13: EPIC-1 | E13: Sprint 1 | F13: Enrutador con rutas públicas, protegidas y páginas provisionales | G13: routes/AppRouter.jsx con las rutas del README (/login, /estudiante/*, /docente/*, /admin, /no-autorizado, 404). Cada ruta protegida envuelta en ProtectedRoute con su rol. Páginas provisionales (título + "en construcción") por pantalla, para que cada integrante reemplace la suya. Página NoAutorizado y NotFound. "/" redirige según el rol o a /login. | H13: • Navegar a una ruta sin sesión lleva a /login. • Un ESTUDIANTE que entra a /docente ve /no-autorizado. • Una URL inexistente muestra la página 404. | J13: 2 | L13: 30/09/2026 | M13: 01/10/2026 | N13: Alta | O13: Por hacer | P13: Nicolás Pérez | Q13: frontend | S13: =G13&IF(H13="","",CHAR(10)&CHAR(10)&"Criterios de aceptación:"&CHAR(10)&H13) -> routes/AppRouter.jsx con las rutas del README (/login, /estudiante/*, /docente/*, /admin, /no-autorizado, 404). Cada ruta protegida envuelta en ProtectedRoute con su rol. Páginas provisionales (título + "en construcción") por pantalla, para que cada integrante reemplace la suya. Página NoAutorizado y NotFound. "/" redirige según el rol o a /login. Criterios de aceptación: • Navegar a una ruta sin sesión lleva a /login. • Un ESTUDIANTE que entra a /docente ve /no-autorizado. • Una URL inexistente muestra la página 404.
A14: 13 | B14: 9 | C14: Subtarea | D14: EPIC-1 | E14: Sprint 1 | F14: Layouts por rol con navegación responsive | G14: layouts/EstudianteLayout, DocenteLayout y AdminLayout: AppBar con nombre del usuario y cerrar sesión, menú lateral con las opciones del rol (Drawer permanente en escritorio, temporal en móvil) y <Outlet/> para el contenido. Accesibilidad: landmarks (header, nav, main), enlace "Saltar al contenido", foco visible, menú operable con teclado. | H14: • Cada rol ve solo sus opciones de menú. • En 375 px de ancho el menú se abre como cajón y no hay scroll horizontal. • Todo el menú se recorre con Tab y se activa con Enter. | J14: 3 | L14: 30/09/2026 | M14: 01/10/2026 | N14: Alta | O14: Por hacer | P14: Nicolás Pérez | Q14: frontend | S14: =G14&IF(H14="","",CHAR(10)&CHAR(10)&"Criterios de aceptación:"&CHAR(10)&H14) -> layouts/EstudianteLayout, DocenteLayout y AdminLayout: AppBar con nombre del usuario y cerrar sesión, menú lateral con las opciones del rol (Drawer permanente en escritorio, temporal en móvil) y <Outlet/> para el contenido. Accesibilidad: landmarks (header, nav, main), enlace "Saltar al contenido", foco visible, menú operable con teclado. Criterios de aceptación: • Cada rol ve solo sus opciones de menú. • En 375 px de ancho el menú se abre como cajón y no hay scroll horizontal. • Todo el menú se recorre con Tab y se activa con Enter.
A15: 14 | C15: Tarea | D15: EPIC-1 | E15: Sprint 1 | F15: Diseñar y crear el esquema inicial de base de datos | G15: Modelo físico y migración Flyway de las tablas base (rol, usuario, competencia), a partir del modelo conceptual del capítulo 4, más sus entidades JPA y los datos semilla necesarios para desarrollar. | H15: • Al arrancar en limpio, Flyway crea las tablas y la app arranca con ddl-auto: validate sin errores. • Existen los 3 roles, las 3 competencias y un usuario de prueba por rol. • La prueba de integración del esquema pasa en CI. | I15: - | K15: =IF(COUNTIF($B$2:$B$150,A15)>0,SUMIFS($J$2:$J$150,$B$2:$B$150,A15)+N(J15),J15) -> 10 | L15: 28/09/2026 | M15: 08/10/2026 | N15: Alta | O15: Por hacer | P15: Juan David Polanco | Q15: backend bd | S15: =G15&IF(H15="","",CHAR(10)&CHAR(10)&"Criterios de aceptación:"&CHAR(10)&H15) -> Modelo físico y migración Flyway de las tablas base (rol, usuario, competencia), a partir del modelo conceptual del capítulo 4, más sus entidades JPA y los datos semilla necesarios para desarrollar. Criterios de aceptación: • Al arrancar en limpio, Flyway crea las tablas y la app arranca con ddl-auto: validate sin errores. • Existen los 3 roles, las 3 competencias y un usuario de prueba por rol. • La prueba de integración del esquema pasa en CI.
A16: 15 | B16: 14 | C16: Subtarea | D16: EPIC-1 | E16: Sprint 1 | F16: Definir el modelo físico de rol, usuario y competencia | G16: Documentar en la tarjeta: rol(id, nombre UNIQUE: ESTUDIANTE, DOCENTE, ADMIN); usuario(id, nombres, apellidos, correo UNIQUE, password_hash, rol_id FK, programa_academico NULL, estado ACTIVO/INACTIVO, creado_en, actualizado_en); competencia(id, codigo UNIQUE: ALGEBRAICA, LOGICA, FUNCIONAL, nombre, descripcion). Tipos: BIGINT GENERATED ALWAYS AS IDENTITY, VARCHAR con longitudes, TIMESTAMPTZ. Convención: tablas y columnas en snake_case singular. | H16: • El modelo está en la tarjeta y lo revisó Jorel antes de escribir la migración. | J16: 2 | L16: 30/09/2026 | M16: 30/09/2026 | N16: Alta | O16: Por hacer | P16: Juan David Polanco | Q16: bd | S16: =G16&IF(H16="","",CHAR(10)&CHAR(10)&"Criterios de aceptación:"&CHAR(10)&H16) -> Documentar en la tarjeta: rol(id, nombre UNIQUE: ESTUDIANTE, DOCENTE, ADMIN); usuario(id, nombres, apellidos, correo UNIQUE, password_hash, rol_id FK, programa_academico NULL, estado ACTIVO/INACTIVO, creado_en, actualizado_en); competencia(id, codigo UNIQUE: ALGEBRAICA, LOGICA, FUNCIONAL, nombre, descripcion). Tipos: BIGINT GENERATED ALWAYS AS IDENTITY, VARCHAR con longitudes, TIMESTAMPTZ. Convención: tablas y columnas en snake_case singular. Criterios de aceptación: • El modelo está en la tarjeta y lo revisó Jorel antes de escribir la migración.
A17: 16 | B17: 14 | C17: Subtarea | D17: EPIC-1 | E17: Sprint 1 | F17: Escribir la migración V1 (rol, usuario, competencia) | G17: db/migration/V<yyyyMMddHHmm>__esquema_inicial.sql con CREATE TABLE, PK, FK usuario.rol_id → rol.id, UNIQUE en correo y códigos, CHECK en estado, índice en usuario.correo. | H17: • La migración corre en una base vacía sin errores. • Insertar dos usuarios con el mismo correo falla. | J17: 3 | L17: 30/09/2026 | M17: 01/10/2026 | N17: Alta | O17: Por hacer | P17: Juan David Polanco | Q17: bd | S17: =G17&IF(H17="","",CHAR(10)&CHAR(10)&"Criterios de aceptación:"&CHAR(10)&H17) -> db/migration/V<yyyyMMddHHmm>__esquema_inicial.sql con CREATE TABLE, PK, FK usuario.rol_id → rol.id, UNIQUE en correo y códigos, CHECK en estado, índice en usuario.correo. Criterios de aceptación: • La migración corre en una base vacía sin errores. • Insertar dos usuarios con el mismo correo falla.
A18: 17 | B18: 14 | C18: Subtarea | D18: EPIC-1 | E18: Sprint 1 | F18: Entidades JPA y repositorios de rol, usuario y competencia | G18: Rol, Usuario (@ManyToOne a Rol), Competencia en sus módulos; RolRepository, UsuarioRepository (findByCorreo, existsByCorreo), CompetenciaRepository (findByCodigo). Enum EstadoUsuario. | H18: • La app arranca con ddl-auto: validate (el mapeo coincide con la migración). | J18: 2 | L18: 01/10/2026 | M18: 01/10/2026 | N18: Alta | O18: Por hacer | P18: Juan David Polanco | Q18: backend | S18: =G18&IF(H18="","",CHAR(10)&CHAR(10)&"Criterios de aceptación:"&CHAR(10)&H18) -> Rol, Usuario (@ManyToOne a Rol), Competencia en sus módulos; RolRepository, UsuarioRepository (findByCorreo, existsByCorreo), CompetenciaRepository (findByCodigo). Enum EstadoUsuario. Criterios de aceptación: • La app arranca con ddl-auto: validate (el mapeo coincide con la migración).
A19: 18 | B19: 14 | C19: Subtarea | D19: EPIC-1 | E19: Sprint 1 | F19: Datos semilla: roles, competencias y usuarios de prueba | G19: Migración de datos con los 3 roles y 3 competencias (se requieren en todos los entornos). Usuarios de prueba (estudiante, docente, admin) con contraseña en BCrypt en una ubicación solo para dev/staging (ej. db/dev-data, agregada a spring.flyway.locations en application-dev.yml). Completar la tabla de usuarios de prueba del README. | H19: • Con perfil dev se puede iniciar sesión con los 3 usuarios de prueba. • Con perfil test/producción no existen usuarios de prueba. | J19: 2 | L19: 01/10/2026 | M19: 01/10/2026 | N19: Alta | O19: Por hacer | P19: Juan David Polanco | Q19: bd | S19: =G19&IF(H19="","",CHAR(10)&CHAR(10)&"Criterios de aceptación:"&CHAR(10)&H19) -> Migración de datos con los 3 roles y 3 competencias (se requieren en todos los entornos). Usuarios de prueba (estudiante, docente, admin) con contraseña en BCrypt en una ubicación solo para dev/staging (ej. db/dev-data, agregada a spring.flyway.locations en application-dev.yml). Completar la tabla de usuarios de prueba del README. Criterios de aceptación: • Con perfil dev se puede iniciar sesión con los 3 usuarios de prueba. • Con perfil test/producción no existen usuarios de prueba.
A20: 19 | B20: 14 | C20: Subtarea | D20: EPIC-1 | E20: Sprint 1 | F20: Prueba de integración del esquema | G20: Prueba con Testcontainers que arranca PostgreSQL, aplica las migraciones y verifica guardar/leer un usuario con su rol. | H20: • ./mvnw test pasa localmente y en CI. | J20: 1 | L20: 02/10/2026 | M20: 04/10/2026 | N20: Alta | O20: Por hacer | P20: Juan David Polanco | Q20: backend qa | S20: =G20&IF(H20="","",CHAR(10)&CHAR(10)&"Criterios de aceptación:"&CHAR(10)&H20) -> Prueba con Testcontainers que arranca PostgreSQL, aplica las migraciones y verifica guardar/leer un usuario con su rol. Criterios de aceptación: • ./mvnw test pasa localmente y en CI.
A21: 20 | C21: Historia | D21: EPIC-1 | E21: Sprint 1 | F21: Implementar registro e inicio de sesión de usuarios | G21: Como usuario quiero iniciar sesión con mi correo y contraseña para acceder a las funciones de mi rol. Autenticación stateless con JWT firmado (HS256) emitido por el backend con Spring Security + OAuth2 Resource Server (Nimbus). Registro público solo para estudiantes; docentes y administradores los crea el administrador (confirmar con el equipo). | H21: • POST /api/auth/login con credenciales válidas devuelve 200 con token, expiración y datos del usuario (id, nombre, rol). • Credenciales inválidas o usuario INACTIVO devuelven 401 con mensaje genérico (no revela si el correo existe). • Las contraseñas se guardan con BCrypt; nunca viajan de vuelta en ninguna respuesta. • Desde el frontend, el login redirige al inicio del rol correspondiente. | I21: RF-01 | K21: =IF(COUNTIF($B$2:$B$150,A21)>0,SUMIFS($J$2:$J$150,$B$2:$B$150,A21)+N(J21),J21) -> 13 | L21: 28/09/2026 | M21: 08/10/2026 | N21: Alta | O21: Por hacer | P21: Jorel Vargas | Q21: backend frontend seguridad | S21: =G21&IF(H21="","",CHAR(10)&CHAR(10)&"Criterios de aceptación:"&CHAR(10)&H21) -> Como usuario quiero iniciar sesión con mi correo y contraseña para acceder a las funciones de mi rol. Autenticación stateless con JWT firmado (HS256) emitido por el backend con Spring Security + OAuth2 Resource Server (Nimbus). Registro público solo para estudiantes; docentes y administradores los crea el administrador (confirmar con el equipo). Criterios de aceptación: • POST /api/auth/login con credenciales válidas devuelve 200 con token, expiración y datos del usuario (id, nombre, rol). • Credenciales inválidas o usuario INACTIVO devuelven 401 con mensaje genérico (no revela si el correo existe). • Las contraseñas se guardan con BCrypt; nunca viajan de vuelta en ninguna respuesta. • Desde el frontend, el login redirige al inicio del rol correspondiente.
A22: 21 | B22: 20 | C22: Subtarea | D22: EPIC-1 | E22: Sprint 1 | F22: Publicar el contrato de /api/auth en la tarjeta | G22: Primera cosa del día para desbloquear a Fernando. POST /api/auth/login body {"correo","password"} → 200 {"token","tipo":"Bearer","expiraEn","usuario":{"id","nombres","rol"}}; 401 {formato estándar}. POST /api/auth/registro (estudiante) → 201. GET /api/auth/me (token) → 200 usuario. Claims del token: sub (id), correo, rol, iat, exp. | H22: • Fernando confirma que puede simular las respuestas con ese contrato. | J22: 1 | L22: 30/09/2026 | M22: 30/09/2026 | N22: Alta | O22: Por hacer | P22: Jorel Vargas | Q22: backend | S22: =G22&IF(H22="","",CHAR(10)&CHAR(10)&"Criterios de aceptación:"&CHAR(10)&H22) -> Primera cosa del día para desbloquear a Fernando. POST /api/auth/login body {"correo","password"} → 200 {"token","tipo":"Bearer","expiraEn","usuario":{"id","nombres","rol"}}; 401 {formato estándar}. POST /api/auth/registro (estudiante) → 201. GET /api/auth/me (token) → 200 usuario. Claims del token: sub (id), correo, rol, iat, exp. Criterios de aceptación: • Fernando confirma que puede simular las respuestas con ese contrato.
A23: 22 | B23: 20 | C23: Subtarea | D23: EPIC-1 | E23: Sprint 1 | F23: PasswordEncoder y UserDetailsService por correo | G23: Bean BCryptPasswordEncoder; UserDetailsService que busca por correo y rechaza usuarios INACTIVOS; AuthenticationManager (DaoAuthenticationProvider). | H23: • Una contraseña correcta autentica y una incorrecta lanza BadCredentials. | J23: 2 | L23: 30/09/2026 | M23: 30/09/2026 | N23: Alta | O23: Por hacer | P23: Jorel Vargas | Q23: backend seguridad | S23: =G23&IF(H23="","",CHAR(10)&CHAR(10)&"Criterios de aceptación:"&CHAR(10)&H23) -> Bean BCryptPasswordEncoder; UserDetailsService que busca por correo y rechaza usuarios INACTIVOS; AuthenticationManager (DaoAuthenticationProvider). Criterios de aceptación: • Una contraseña correcta autentica y una incorrecta lanza BadCredentials.
A24: 23 | B24: 20 | C24: Subtarea | D24: EPIC-1 | E24: Sprint 1 | F24: Servicio JWT: emisión y validación del token | G24: JwtEncoder/JwtDecoder de Nimbus con clave simétrica desde app.jwt.secret (mínimo 32 caracteres), expiración desde app.jwt.expiration-minutes, claims sub, correo, rol. Configurar oauth2ResourceServer().jwt() en SecurityConfig. | H24: • Un token emitido es aceptado; uno alterado o vencido responde 401. | J24: 2 | L24: 30/09/2026 | M24: 01/10/2026 | N24: Alta | O24: Por hacer | P24: Jorel Vargas | Q24: backend seguridad | S24: =G24&IF(H24="","",CHAR(10)&CHAR(10)&"Criterios de aceptación:"&CHAR(10)&H24) -> JwtEncoder/JwtDecoder de Nimbus con clave simétrica desde app.jwt.secret (mínimo 32 caracteres), expiración desde app.jwt.expiration-minutes, claims sub, correo, rol. Configurar oauth2ResourceServer().jwt() en SecurityConfig. Criterios de aceptación: • Un token emitido es aceptado; uno alterado o vencido responde 401.
A25: 24 | B25: 20 | C25: Subtarea | D25: EPIC-1 | E25: Sprint 1 | F25: Endpoints /api/auth/login, /registro y /me | G25: AuthController + AuthService con DTO validados (LoginRequest, RegistroRequest, AuthResponse, UsuarioResponse). Registro asigna rol ESTUDIANTE y valida correo único (409 si existe). | H25: • Los tres endpoints cumplen el contrato publicado y aparecen en Swagger. | J25: 2 | L25: 01/10/2026 | M25: 01/10/2026 | N25: Alta | O25: Por hacer | P25: Jorel Vargas | Q25: backend | S25: =G25&IF(H25="","",CHAR(10)&CHAR(10)&"Criterios de aceptación:"&CHAR(10)&H25) -> AuthController + AuthService con DTO validados (LoginRequest, RegistroRequest, AuthResponse, UsuarioResponse). Registro asigna rol ESTUDIANTE y valida correo único (409 si existe). Criterios de aceptación: • Los tres endpoints cumplen el contrato publicado y aparecen en Swagger.
A26: 25 | B26: 20 | C26: Subtarea | D26: EPIC-1 | E26: Sprint 1 | F26: Pruebas del login | G26: Pruebas de servicio y de controlador (MockMvc): login correcto, contraseña errada, usuario inactivo, registro con correo repetido, /me sin token. | H26: • Las 5 pruebas pasan en CI. | J26: 1 | L26: 02/10/2026 | M26: 04/10/2026 | N26: Alta | O26: Por hacer | P26: Jorel Vargas | Q26: backend qa | S26: =G26&IF(H26="","",CHAR(10)&CHAR(10)&"Criterios de aceptación:"&CHAR(10)&H26) -> Pruebas de servicio y de controlador (MockMvc): login correcto, contraseña errada, usuario inactivo, registro con correo repetido, /me sin token. Criterios de aceptación: • Las 5 pruebas pasan en CI.
A27: 26 | B27: 20 | C27: Subtarea | D27: EPIC-1 | E27: Sprint 1 | F27: Cliente authApi con datos simulados | G27: api/authApi.js con login(), registro() y me(). Mientras el endpoint no esté en develop, responde con datos simulados (usuarios de prueba por rol y un token falso con la misma forma del contrato) activados con VITE_USE_MOCKS=true. | H27: • Cambiar VITE_USE_MOCKS a false usa el backend real sin tocar componentes. | J27: 1 | L27: 30/09/2026 | M27: 30/09/2026 | N27: Alta | O27: Por hacer | P27: Fernando Pérez | Q27: frontend | R27: Nueva en v3 | S27: =G27&IF(H27="","",CHAR(10)&CHAR(10)&"Criterios de aceptación:"&CHAR(10)&H27) -> api/authApi.js con login(), registro() y me(). Mientras el endpoint no esté en develop, responde con datos simulados (usuarios de prueba por rol y un token falso con la misma forma del contrato) activados con VITE_USE_MOCKS=true. Criterios de aceptación: • Cambiar VITE_USE_MOCKS a false usa el backend real sin tocar componentes.
A28: 27 | B28: 20 | C28: Subtarea | D28: EPIC-1 | E28: Sprint 1 | F28: Pantalla de inicio de sesión | G28: features/auth/LoginPage.jsx según el prototipo: correo y contraseña con react-hook-form + zod (correo válido, contraseña requerida), botón con estado de carga, mensaje de error del servidor, mostrar/ocultar contraseña. Accesible: labels visibles, errores asociados con aria-describedby, foco al primer error, envío con Enter. Al iniciar sesión redirige a /estudiante, /docente o /admin según el rol. | H28: • Con credenciales de prueba entra al inicio del rol correcto. • Con credenciales inválidas muestra el error sin recargar la página. • Se puede completar solo con teclado. • Se ve bien en 375 px de ancho. | J28: 4 | L28: 30/09/2026 | M28: 01/10/2026 | N28: Alta | O28: Por hacer | P28: Fernando Pérez | Q28: frontend | R28: Nueva en v3 | S28: =G28&IF(H28="","",CHAR(10)&CHAR(10)&"Criterios de aceptación:"&CHAR(10)&H28) -> features/auth/LoginPage.jsx según el prototipo: correo y contraseña con react-hook-form + zod (correo válido, contraseña requerida), botón con estado de carga, mensaje de error del servidor, mostrar/ocultar contraseña. Accesible: labels visibles, errores asociados con aria-describedby, foco al primer error, envío con Enter. Al iniciar sesión redirige a /estudiante, /docente o /admin según el rol. Criterios de aceptación: • Con credenciales de prueba entra al inicio del rol correcto. • Con credenciales inválidas muestra el error sin recargar la página. • Se puede completar solo con teclado. • Se ve bien en 375 px de ancho.
A29: 28 | C29: Historia | D29: EPIC-1 | E29: Sprint 1 | F29: Implementar control de acceso por rol | G29: Como plataforma debo restringir endpoints (backend) y vistas (frontend) según el rol ESTUDIANTE, DOCENTE o ADMIN. El backend es la barrera real; el frontend solo evita navegar a lo que no corresponde. | H29: • Un token de ESTUDIANTE que llama un endpoint de DOCENTE recibe 403 con el formato estándar. • Una petición sin token recibe 401. • En el frontend, cada rol solo puede navegar a sus rutas y al vencer el token vuelve al login. | I29: RF-01, RNF-03 | K29: =IF(COUNTIF($B$2:$B$150,A29)>0,SUMIFS($J$2:$J$150,$B$2:$B$150,A29)+N(J29),J29) -> 8 | L29: 28/09/2026 | M29: 08/10/2026 | N29: Alta | O29: Por hacer | P29: Jorel Vargas | Q29: backend frontend seguridad | S29: =G29&IF(H29="","",CHAR(10)&CHAR(10)&"Criterios de aceptación:"&CHAR(10)&H29) -> Como plataforma debo restringir endpoints (backend) y vistas (frontend) según el rol ESTUDIANTE, DOCENTE o ADMIN. El backend es la barrera real; el frontend solo evita navegar a lo que no corresponde. Criterios de aceptación: • Un token de ESTUDIANTE que llama un endpoint de DOCENTE recibe 403 con el formato estándar. • Una petición sin token recibe 401. • En el frontend, cada rol solo puede navegar a sus rutas y al vencer el token vuelve al login.
A30: 29 | B30: 28 | C30: Subtarea | D30: EPIC-1 | E30: Sprint 1 | F30: Autorización por rol en el backend | G30: JwtAuthenticationConverter que convierte el claim "rol" en ROLE_<rol>; @EnableMethodSecurity y @PreAuthorize en controladores; AuthenticationEntryPoint (401) y AccessDeniedHandler (403) que responden con el formato estándar. | H30: • Endpoint de prueba /api/ping/{rol} responde 200 al rol correcto y 403 a los demás. | J30: 3 | L30: 02/10/2026 | M30: 04/10/2026 | N30: Alta | O30: Por hacer | P30: Jorel Vargas | Q30: backend seguridad | S30: =G30&IF(H30="","",CHAR(10)&CHAR(10)&"Criterios de aceptación:"&CHAR(10)&H30) -> JwtAuthenticationConverter que convierte el claim "rol" en ROLE_<rol>; @EnableMethodSecurity y @PreAuthorize en controladores; AuthenticationEntryPoint (401) y AccessDeniedHandler (403) que responden con el formato estándar. Criterios de aceptación: • Endpoint de prueba /api/ping/{rol} responde 200 al rol correcto y 403 a los demás.
A31: 30 | B31: 28 | C31: Subtarea | D31: EPIC-1 | E31: Sprint 1 | F31: AuthContext: sesión, rol y cierre de sesión | G31: context/AuthContext.jsx con user, rol, login(), logout(), isAuthenticated. Lee el token con jwt-decode al cargar la app, descarta tokens vencidos y lo guarda en localStorage. | H31: • Al recargar la página la sesión se mantiene si el token sigue vigente. • logout limpia el token y lleva a /login. | J31: 2 | L31: 30/09/2026 | M31: 01/10/2026 | N31: Alta | O31: Por hacer | P31: Fernando Pérez | Q31: frontend | S31: =G31&IF(H31="","",CHAR(10)&CHAR(10)&"Criterios de aceptación:"&CHAR(10)&H31) -> context/AuthContext.jsx con user, rol, login(), logout(), isAuthenticated. Lee el token con jwt-decode al cargar la app, descarta tokens vencidos y lo guarda en localStorage. Criterios de aceptación: • Al recargar la página la sesión se mantiene si el token sigue vigente. • logout limpia el token y lleva a /login.
A32: 31 | B32: 28 | C32: Subtarea | D32: EPIC-1 | E32: Sprint 1 | F32: ProtectedRoute e interceptor de 401 | G32: Conectar ProtectedRoute con AuthContext (sin sesión → /login guardando la ruta de origen; rol distinto → /no-autorizado). Interceptor de respuesta en api/client.js: ante 401 hace logout y redirige al login. | H32: • Tras iniciar sesión, vuelve a la ruta que el usuario intentaba abrir. • Un 401 del backend cierra la sesión automáticamente. | J32: 2 | L32: 01/10/2026 | M32: 01/10/2026 | N32: Alta | O32: Por hacer | P32: Fernando Pérez | Q32: frontend | S32: =G32&IF(H32="","",CHAR(10)&CHAR(10)&"Criterios de aceptación:"&CHAR(10)&H32) -> Conectar ProtectedRoute con AuthContext (sin sesión → /login guardando la ruta de origen; rol distinto → /no-autorizado). Interceptor de respuesta en api/client.js: ante 401 hace logout y redirige al login. Criterios de aceptación: • Tras iniciar sesión, vuelve a la ruta que el usuario intentaba abrir. • Un 401 del backend cierra la sesión automáticamente.
A33: 32 | B33: 28 | C33: Subtarea | D33: EPIC-1 | E33: Sprint 1 | F33: Pruebas de acceso por rol | G33: Pruebas MockMvc de 401 y 403 sobre endpoints de cada rol, reutilizables en la tarea de hardening del Sprint 4. | H33: • Pasan en CI. | J33: 1 | L33: 02/10/2026 | M33: 04/10/2026 | N33: Alta | O33: Por hacer | P33: Jorel Vargas | Q33: backend qa | S33: =G33&IF(H33="","",CHAR(10)&CHAR(10)&"Criterios de aceptación:"&CHAR(10)&H33) -> Pruebas MockMvc de 401 y 403 sobre endpoints de cada rol, reutilizables en la tarea de hardening del Sprint 4. Criterios de aceptación: • Pasan en CI.
A34: 33 | C34: Tarea | D34: EPIC-1 | E34: Sprint 1 | F34: Configurar entorno de despliegue de prueba (staging) | G34: Backend, base de datos y frontend publicados en una URL accesible para el equipo y los usuarios piloto, con variables de entorno separadas y despliegue desde develop. | H34: • El equipo abre la URL de staging e inicia sesión con un usuario de prueba. • Un merge a develop se refleja en staging (automático o con un paso documentado). • Ningún secreto está en el repositorio. | I34: - | K34: =IF(COUNTIF($B$2:$B$150,A34)>0,SUMIFS($J$2:$J$150,$B$2:$B$150,A34)+N(J34),J34) -> 8 | L34: 28/09/2026 | M34: 08/10/2026 | N34: Media | O34: Por hacer | P34: Nicolás Pérez | Q34: devops | S34: =G34&IF(H34="","",CHAR(10)&CHAR(10)&"Criterios de aceptación:"&CHAR(10)&H34) -> Backend, base de datos y frontend publicados en una URL accesible para el equipo y los usuarios piloto, con variables de entorno separadas y despliegue desde develop. Criterios de aceptación: • El equipo abre la URL de staging e inicia sesión con un usuario de prueba. • Un merge a develop se refleja en staging (automático o con un paso documentado). • Ningún secreto está en el repositorio.
A35: 34 | B35: 33 | C35: Subtarea | D35: EPIC-1 | E35: Sprint 1 | F35: Elegir la plataforma de hosting | G35: Comparar 2 o 3 opciones gratuitas o con crédito estudiantil para Spring Boot + PostgreSQL y para un sitio estático (límites, suspensión por inactividad, región). Registrar la decisión en la tarjeta. | H35: • Decisión escrita con el motivo. | J35: 1 | L35: 02/10/2026 | M35: 04/10/2026 | N35: Media | O35: Por hacer | P35: Nicolás Pérez | Q35: devops | S35: =G35&IF(H35="","",CHAR(10)&CHAR(10)&"Criterios de aceptación:"&CHAR(10)&H35) -> Comparar 2 o 3 opciones gratuitas o con crédito estudiantil para Spring Boot + PostgreSQL y para un sitio estático (límites, suspensión por inactividad, región). Registrar la decisión en la tarjeta. Criterios de aceptación: • Decisión escrita con el motivo.
A36: 35 | B36: 33 | C36: Subtarea | D36: EPIC-1 | E36: Sprint 1 | F36: Desplegar backend y PostgreSQL | G36: Servicio del backend (Dockerfile o build nativo de la plataforma), base PostgreSQL gestionada, variables SPRING_PROFILES_ACTIVE, SPRING_DATASOURCE_*, JWT_SECRET, CORS_ORIGINS. | H36: • /actuator/health de staging responde UP. | J36: 3 | L36: 28/09/2026 | M36: 08/10/2026 | N36: Media | O36: Por hacer | P36: Nicolás Pérez | Q36: devops | S36: =G36&IF(H36="","",CHAR(10)&CHAR(10)&"Criterios de aceptación:"&CHAR(10)&H36) -> Servicio del backend (Dockerfile o build nativo de la plataforma), base PostgreSQL gestionada, variables SPRING_PROFILES_ACTIVE, SPRING_DATASOURCE_*, JWT_SECRET, CORS_ORIGINS. Criterios de aceptación: • /actuator/health de staging responde UP.
A37: 36 | B37: 33 | C37: Subtarea | D37: EPIC-1 | E37: Sprint 1 | F37: Desplegar frontend | G37: Build de Vite con VITE_API_URL de staging; regla de reescritura para que las rutas de React Router no den 404 al recargar. | H37: • Recargar /estudiante en staging no da 404. | J37: 2 | L37: 28/09/2026 | M37: 08/10/2026 | N37: Media | O37: Por hacer | P37: Nicolás Pérez | Q37: devops | S37: =G37&IF(H37="","",CHAR(10)&CHAR(10)&"Criterios de aceptación:"&CHAR(10)&H37) -> Build de Vite con VITE_API_URL de staging; regla de reescritura para que las rutas de React Router no den 404 al recargar. Criterios de aceptación: • Recargar /estudiante en staging no da 404.
A38: 37 | B38: 33 | C38: Subtarea | D38: EPIC-1 | E38: Sprint 1 | F38: Documentar URLs y proceso de despliegue | G38: Sección "Despliegue" en ambos README: URLs, variables, cómo desplegar y quién tiene acceso a la plataforma. | H38: • Cualquier integrante puede redesplegar siguiendo el README. | J38: 2 | L38: 28/09/2026 | M38: 08/10/2026 | N38: Media | O38: Por hacer | P38: Nicolás Pérez | Q38: docs | S38: =G38&IF(H38="","",CHAR(10)&CHAR(10)&"Criterios de aceptación:"&CHAR(10)&H38) -> Sección "Despliegue" en ambos README: URLs, variables, cómo desplegar y quién tiene acceso a la plataforma. Criterios de aceptación: • Cualquier integrante puede redesplegar siguiendo el README.
A39: 38 | C39: Tarea | D39: EPIC-1 | E39: Sprint 1 | F39: Configurar integración continua básica | G39: GitHub Actions que compila y prueba cada PR hacia develop y main en ambos repositorios, y que se exige como check obligatorio antes de fusionar. | H39: • Un PR con una prueba fallando no se puede fusionar. • El pipeline tarda menos de 10 minutos. | I39: - | K39: =IF(COUNTIF($B$2:$B$150,A39)>0,SUMIFS($J$2:$J$150,$B$2:$B$150,A39)+N(J39),J39) -> 6 | L39: 28/09/2026 | M39: 08/10/2026 | N39: Media | O39: Por hacer | P39: Fernando Pérez | Q39: devops qa | S39: =G39&IF(H39="","",CHAR(10)&CHAR(10)&"Criterios de aceptación:"&CHAR(10)&H39) -> GitHub Actions que compila y prueba cada PR hacia develop y main en ambos repositorios, y que se exige como check obligatorio antes de fusionar. Criterios de aceptación: • Un PR con una prueba fallando no se puede fusionar. • El pipeline tarda menos de 10 minutos.
A40: 39 | B40: 38 | C40: Subtarea | D40: EPIC-1 | E40: Sprint 1 | F40: Workflow del backend | G40: .github/workflows/ci.yml: Temurin 21, caché de Maven, ./mvnw verify (Testcontainers funciona en los runners de GitHub). | H40: • Corre en cada PR y muestra el resultado en el PR. | J40: 2 | L40: 02/10/2026 | M40: 04/10/2026 | N40: Media | O40: Por hacer | P40: Fernando Pérez | Q40: devops | S40: =G40&IF(H40="","",CHAR(10)&CHAR(10)&"Criterios de aceptación:"&CHAR(10)&H40) -> .github/workflows/ci.yml: Temurin 21, caché de Maven, ./mvnw verify (Testcontainers funciona en los runners de GitHub). Criterios de aceptación: • Corre en cada PR y muestra el resultado en el PR.
...
